#VRML_SIM V8.6 utf8
WorldInfo {
  info [
    "Description"
    "Author: first name last name <e-mail>"
    "Date: DD MMM YYYY"
  ]
  physics "no_lift"
  basicTimeStep 1
  contactProperties [
    DEF CONTACT ContactProperties {
    }
  ]
}
Viewpoint {
  orientation -0.0041610417 0.99997884 -0.0050002496 4.529979
  position -2.7340856 0.54445789 -0.60910269
}
Background {
  skyColor [
    0.658824 0.827451 1
  ]
}
DirectionalLight {
  direction 0 -1 1
  castShadows TRUE
}
DirectionalLight {
}
DEF REGIS Supervisor {
  translation 0 1.53 0
  rotation 1 0 0 0.2
  children [
    DEF RECEIVER Receiver {
      name "RECEIVER"
      channel 1
    }
    DEF EMITTER Emitter {
      name "EMITTER"
    }
    DEF LEFT_LEG Solid {
      translation 0.08 -0.4 0
      children [
        DEF LEFT_HIP HingeJoint {
          jointParameters HingeJointParameters {
          }
          device [
            RotationalMotor {
              name "HIP_LEFT"
              maxTorque 200
            }
            PositionSensor {
              name "HIP_LEFT_POS"
            }
          ]
          endPoint DEF LEFT_THIGH Solid {
            children [
              Transform {
                translation 0 -0.5 0
                children [
                  DEF LEFT_KNEE HingeJoint {
                    jointParameters HingeJointParameters {
                    }
                    device [
                      RotationalMotor {
                        name "KNEE_LEFT"
                        maxTorque 200
                      }
                      PositionSensor {
                        name "KNEE_LEFT_POS"
                      }
                    ]
                    endPoint DEF LEFT_SHIN Solid {
                      rotation 1 0 0 0
                      children [
                        Transform {
                          translation 0 -0.5 0
                          children [
                            DEF LEFT_ANKLE HingeJoint {
                              jointParameters HingeJointParameters {
                              }
                              device [
                                RotationalMotor {
                                  name "ANKLE_LEFT"
                                  maxTorque 200
                                }
                                PositionSensor {
                                  name "ANKLE_LEFT_POS"
                                }
                              ]
                              endPoint DEF LEFT_FOOT Solid {
                                rotation -1 0 0 0.085
                                children [
                                  Transform {
                                    translation 0 -0.075 0.06
                                    rotation 1 0 0 1.57
                                    children [
                                      DEF SENSOR_HEEL_LEFT TouchSensor {
                                        name "SENSOR_HEEL_LEFT"
                                        boundingObject Transform {
                                          translation 0 -0.075 0
                                          rotation 1 0 0 0
                                          children [
                                            Sphere {
                                              radius 0.05
                                            }
                                          ]
                                        }
                                        physics Physics {
                                          density -1
                                          mass 1e-08
                                        }
                                        type "force-3d"
                                        lookupTable []
                                      }
                                      DEF SENSOR_HEEL_LEFT2 TouchSensor {
                                        translation 0 -0.15 0
                                        rotation 1 0 0 3.14
                                        name "SENSOR_HEEL_LEFT2"
                                        boundingObject Transform {
                                          translation 0 -0.075 0
                                          rotation 1 0 0 0
                                          children [
                                            Sphere {
                                              radius 0.05
                                            }
                                          ]
                                        }
                                        physics Physics {
                                          density -1
                                          mass 1e-08
                                        }
                                        type "force-3d"
                                        lookupTable []
                                      }
                                      DEF SENSOR_TOE_LEFT TouchSensor {
                                        name "SENSOR_TOE_LEFT"
                                        boundingObject Transform {
                                          translation 0 0.075 0
                                          rotation 1 0 0 1.57
                                          children [
                                            Sphere {
                                              radius 0.05
                                            }
                                          ]
                                        }
                                        physics Physics {
                                          density -1
                                          mass 1e-08
                                        }
                                        type "force-3d"
                                        lookupTable []
                                      }
                                      DEF SENSOR_TOE_LEFT2 TouchSensor {
                                        translation 0 0.15 0
                                        rotation 1 0 0 3.14
                                        name "SENSOR_TOE_LEFT2"
                                        boundingObject Transform {
                                          translation 0 0.075 0
                                          rotation 1 0 0 1.57
                                          children [
                                            Sphere {
                                              radius 0.05
                                            }
                                          ]
                                        }
                                        physics Physics {
                                          density -1
                                          mass 1e-08
                                        }
                                        type "force-3d"
                                        lookupTable []
                                      }
                                    ]
                                  }
                                ]
                                name "left foot"
                                physics Physics {
                                  density -1
                                  mass 1.25
                                  centerOfMass [
                                    0 0 0.02
                                  ]
                                  inertiaMatrix [
                                    0.005 0.005 0.005
                                    0 0 0
                                  ]
                                }
                              }
                            }
                          ]
                        }
                      ]
                      name "left shin"
                      boundingObject DEF SHIN Group {
                        children [
                          Transform {
                            translation 0 -0.25 0
                            children [
                              DEF APPEARANCE_SHIN_LEFT Shape {
                                geometry Capsule {
                                  height 0.35
                                  radius 0.05
                                }
                              }
                            ]
                          }
                        ]
                      }
                      physics Physics {
                        density -1
                        mass 3.5
                        centerOfMass [
                          0 -0.2 0
                        ]
                        inertiaMatrix [
                          0.05 0.05 0.05
                          0 0 0
                        ]
                      }
                    }
                  }
                ]
              }
            ]
            name "left thigh"
            boundingObject DEF THIGH Group {
              children [
                Transform {
                  translation 0 -0.25 0
                  children [
                    DEF APPEARANCE_THIGH_LEFT Shape {
                      geometry Capsule {
                        height 0.35
                        radius 0.08
                      }
                    }
                  ]
                }
              ]
            }
            physics Physics {
              density -1
              mass 8.5
              centerOfMass [
                0 -0.2 0
              ]
              inertiaMatrix [
                0.15 0.15 0.15
                0 0 0
              ]
            }
          }
        }
      ]
      name "left leg"
      boundingObject Sphere {
        radius 0.001
      }
      physics Physics {
        density 1
      }
    }
    DEF RIGHT_LEG Solid {
      translation -0.08 -0.4 0
      children [
        DEF RIGHT_HIP HingeJoint {
          jointParameters HingeJointParameters {
          }
          device [
            RotationalMotor {
              name "HIP_RIGHT"
              maxVelocity 100
              maxTorque 200
            }
            PositionSensor {
              name "HIP_RIGHT_POS"
            }
          ]
          endPoint DEF RIGHT_THIGH Solid {
            children [
              Transform {
                translation 0 -0.5 0
                children [
                  DEF RIGHT_KNEE HingeJoint {
                    jointParameters HingeJointParameters {
                    }
                    device [
                      RotationalMotor {
                        name "KNEE_RIGHT"
                        controlPID 100 0 0
                        maxVelocity 100
                        maxTorque 200
                      }
                      PositionSensor {
                        name "KNEE_RIGHT_POS"
                      }
                    ]
                    endPoint DEF RIGHT_SHIN Solid {
                      rotation 1 0 0 0
                      children [
                        Transform {
                          translation 0 -0.5 0
                          children [
                            DEF RIGHT_ANKLE HingeJoint {
                              jointParameters HingeJointParameters {
                              }
                              device [
                                RotationalMotor {
                                  name "ANKLE_RIGHT"
                                  controlPID 100 0 0
                                  maxVelocity 100
                                  maxTorque 200
                                }
                                PositionSensor {
                                  name "ANKLE_RIGHT_POS"
                                }
                              ]
                              endPoint DEF RIGHT_FOOT Solid {
                                rotation -1 0 0 0.085
                                children [
                                  Transform {
                                    translation 0 -0.075 0.06
                                    rotation 1 0 0 1.57
                                    children [
                                      DEF SENSOR_HEEL_RIGHT TouchSensor {
                                        name "SENSOR_HEEL_RIGHT"
                                        boundingObject Transform {
                                          translation 0 -0.075 0
                                          rotation 1 0 0 0
                                          children [
                                            Sphere {
                                              radius 0.05
                                            }
                                          ]
                                        }
                                        physics Physics {
                                          density -1
                                          mass 1e-08
                                        }
                                        type "force-3d"
                                        lookupTable []
                                      }
                                      DEF SENSOR_HEEL_RIGHT2 TouchSensor {
                                        translation 0 -0.15 0
                                        rotation 1 0 0 3.14
                                        name "SENSOR_HEEL_RIGHT2"
                                        boundingObject Transform {
                                          translation 0 -0.075 0
                                          rotation 1 0 0 0
                                          children [
                                            Sphere {
                                              radius 0.05
                                            }
                                          ]
                                        }
                                        physics Physics {
                                          density -1
                                          mass 1e-08
                                        }
                                        type "force-3d"
                                        lookupTable []
                                      }
                                      DEF SENSOR_TOE_RIGHT TouchSensor {
                                        rotation 1 0 0 0
                                        name "SENSOR_TOE_RIGHT"
                                        boundingObject Transform {
                                          translation 0 0.075 0
                                          rotation 1 0 0 1.57
                                          children [
                                            Sphere {
                                              radius 0.05
                                            }
                                          ]
                                        }
                                        physics Physics {
                                          density -1
                                          mass 1e-08
                                        }
                                        type "force-3d"
                                        lookupTable []
                                      }
                                      DEF SENSOR_TOE_RIGHT2 TouchSensor {
                                        translation 0 0.15 0
                                        rotation 1 0 0 3.14
                                        name "SENSOR_TOE_RIGHT2"
                                        boundingObject Transform {
                                          translation 0 0.075 0
                                          rotation 1 0 0 1.57
                                          children [
                                            Sphere {
                                              radius 0.05
                                            }
                                          ]
                                        }
                                        physics Physics {
                                          density -1
                                          mass 1e-08
                                        }
                                        type "force-3d"
                                        lookupTable []
                                      }
                                    ]
                                  }
                                ]
                                name "right foot"
                                physics Physics {
                                  density -1
                                  mass 1.25
                                  centerOfMass [
                                    0 0 0.02
                                  ]
                                  inertiaMatrix [
                                    0.005 0.005 0.005
                                    0 0 0
                                  ]
                                }
                              }
                            }
                          ]
                        }
                      ]
                      name "right shin"
                      boundingObject USE SHIN
                      physics Physics {
                        density -1
                        mass 3.5
                        centerOfMass [
                          0 -0.2 0
                        ]
                        inertiaMatrix [
                          0.05 0.05 0.05
                          0 0 0
                        ]
                      }
                    }
                  }
                ]
              }
            ]
            name "right thigh"
            boundingObject USE THIGH
            physics Physics {
              density -1
              mass 8.5
              centerOfMass [
                0 -0.2 0
              ]
              inertiaMatrix [
                0.15 0.15 0.15
                0 0 0
              ]
            }
          }
        }
      ]
      name "right leg"
      boundingObject Sphere {
        radius 0.001
      }
      physics Physics {
        density 1
      }
    }
    Skin {
      translation 0 -1.53 -0.03
      scale 1 1.09 1
      model "robert"
      appearance [
        Appearance {
          material Material {
          }
          texture ImageTexture {
            url [
              "../skins/robert/robert_skin.jpg"
            ]
          }
          name "body"
        }
        Appearance {
          material Material {
          }
          texture ImageTexture {
            url [
              "../skins/robert/robert_suit.jpg"
            ]
          }
          name "suit"
        }
        Appearance {
          material Material {
          }
          texture ImageTexture {
            url [
              "../skins/robert/robert_hair.png"
            ]
          }
          name "hairs"
        }
        Appearance {
          material Material {
          }
          texture ImageTexture {
            url [
              "../skins/robert/robert_shoes.jpg"
            ]
          }
          name "shoes"
        }
        Appearance {
          material Material {
          }
          texture ImageTexture {
            url [
              "../skins/robert/robert_eyes.jpg"
            ]
          }
          name "eyes"
        }
        Appearance {
          material Material {
          }
          texture ImageTexture {
            url [
              "../skins/robert/robert_eyebrow.png"
            ]
          }
          name "eyebrow"
        }
      ]
      bones [
        SolidReference {
          solidName "right leg"
        }
        SolidReference {
          solidName "right thigh"
        }
        SolidReference {
          solidName "right shin"
        }
        SolidReference {
          solidName "right foot"
        }
        SolidReference {
          solidName "left leg"
        }
        SolidReference {
          solidName "left thigh"
        }
        SolidReference {
          solidName "left shin"
        }
        SolidReference {
          solidName "left foot"
        }
      ]
    }
  ]
  name "REGIS"
  boundingObject DEF TRUNK Transform {
    translation 0 -0.19 0
    children [
      DEF TRUNK Shape {
        geometry Capsule {
          height 0.4
          radius 0.13
        }
      }
    ]
  }
  physics Physics {
    density -1
    mass 53.5
    centerOfMass [
      0 -0.05 0
    ]
    inertiaMatrix [
      3 3 3
      0 0 0
    ]
  }
  controller "regis"
  controllerArgs "3D.xml sample"
}
DEF GROUND Solid {
  children [
    DEF APPEARANCE_GROUND Transform {
      translation 0 0 114
      children [
        Shape {
          appearance Appearance {
            material Material {
              diffuseColor 1 1 1
              transparency 0.01
            }
            texture ImageTexture {
              url [
                "textures/ground.jpg"
              ]
            }
            textureTransform TextureTransform {
              scale 6 300
            }
          }
          geometry Plane {
            size 3 231
          }
        }
      ]
    }
  ]
  name "GROUND"
  boundingObject Plane {
  }
}
DEF MATLAB Supervisor {
  children [
    Receiver {
      channel 2
    }
  ]
}
DEF PYTHON Supervisor {
  children [
    Emitter {
    }
    Receiver {
      channel 2
    }
  ]
}
